Traceback (most recent call last):
  File "c:\users\peter\.conda\envs\photogrammetry\lib\site-packages\jupyter_cache\executors\utils.py", line 56, in single_nb_execution
    record_timing=False,
  File "c:\users\peter\.conda\envs\photogrammetry\lib\site-packages\nbclient\client.py", line 1087, in execute
    return NotebookClient(nb=nb, resources=resources, km=km, **kwargs).execute()
  File "c:\users\peter\.conda\envs\photogrammetry\lib\site-packages\nbclient\util.py", line 74, in wrapped
    return just_run(coro(*args, **kwargs))
  File "c:\users\peter\.conda\envs\photogrammetry\lib\site-packages\nbclient\util.py", line 53, in just_run
    return loop.run_until_complete(coro)
  File "c:\users\peter\.conda\envs\photogrammetry\lib\asyncio\base_events.py", line 587, in run_until_complete
    return future.result()
  File "c:\users\peter\.conda\envs\photogrammetry\lib\site-packages\nbclient\client.py", line 541, in async_execute
    cell, index, execution_count=self.code_cells_executed + 1
  File "c:\users\peter\.conda\envs\photogrammetry\lib\site-packages\nbclient\client.py", line 832, in async_execute_cell
    self._check_raise_for_error(cell, exec_reply)
  File "c:\users\peter\.conda\envs\photogrammetry\lib\site-packages\nbclient\client.py", line 740, in _check_raise_for_error
    raise CellExecutionError.from_cell_and_msg(cell, exec_reply['content'])
nbclient.exceptions.CellExecutionError: An error occurred while executing the following cell:
------------------
config_file = "../config/photogrammetry_processing_settings.yml"
AP(config_file)
------------------

[1;31m---------------------------------------------------------------------------[0m
[1;31mFileNotFoundError[0m                         Traceback (most recent call last)
[1;32m<ipython-input-2-78f7fde85962>[0m in [0;36m<module>[1;34m[0m
[0;32m      1[0m [0mconfig_file[0m [1;33m=[0m [1;34m"../config/photogrammetry_processing_settings.yml"[0m[1;33m[0m[1;33m[0m[0m
[1;32m----> 2[1;33m [0mAP[0m[1;33m([0m[0mconfig_file[0m[1;33m)[0m[1;33m[0m[1;33m[0m[0m
[0m
[1;32m~\.conda\envs\Photogrammetry\lib\site-packages\automated_metashape\MetashapeProcessing.py[0m in [0;36m__init__[1;34m(self, config_file, logger)[0m
[0;32m     53[0m         [1;31m# self._about()[0m[1;33m[0m[1;33m[0m[1;33m[0m[0m
[0;32m     54[0m [1;33m[0m[0m
[1;32m---> 55[1;33m         [0mself[0m[1;33m.[0m[0mcfg[0m [1;33m=[0m [0mread_yaml[0m[1;33m([0m[0mconfig_file[0m[1;33m)[0m[1;33m[0m[1;33m[0m[0m
[0m[0;32m     56[0m         [0mself[0m[1;33m.[0m[0mconfig_file[0m [1;33m=[0m [0mconfig_file[0m[1;33m[0m[1;33m[0m[0m
[0;32m     57[0m [1;33m[0m[0m

[1;32m~\.conda\envs\Photogrammetry\lib\site-packages\automated_metashape\read_yaml.py[0m in [0;36mread_yaml[1;34m(yml_path)[0m
[0;32m     46[0m [1;32mdef[0m [0mread_yaml[0m[1;33m([0m[0myml_path[0m[1;33m)[0m[1;33m:[0m[1;33m[0m[1;33m[0m[0m
[0;32m     47[0m     [0myml_path[0m [1;33m=[0m [0mpathlib[0m[1;33m.[0m[0mPath[0m[1;33m([0m[0myml_path[0m[1;33m)[0m[1;33m[0m[1;33m[0m[0m
[1;32m---> 48[1;33m     [1;32mwith[0m [0mopen[0m[1;33m([0m[0myml_path[0m[1;33m,[0m[1;34m'r'[0m[1;33m)[0m [1;32mas[0m [0mymlfile[0m[1;33m:[0m[1;33m[0m[1;33m[0m[0m
[0m[0;32m     49[0m         [0mcfg[0m [1;33m=[0m [0myaml[0m[1;33m.[0m[0mload[0m[1;33m([0m[0mymlfile[0m[1;33m,[0m [0mLoader[0m[1;33m=[0m[0myaml[0m[1;33m.[0m[0mSafeLoader[0m[1;33m)[0m[1;33m[0m[1;33m[0m[0m
[0;32m     50[0m [1;33m[0m[0m

[1;31mFileNotFoundError[0m: [Errno 2] No such file or directory: '..\\config\\photogrammetry_processing_settings.yml'
FileNotFoundError: [Errno 2] No such file or directory: '..\\config\\photogrammetry_processing_settings.yml'

